<?xml version="1.0"?>
<robot name="manipulator" xmlns:xacro="https://www.ros.org/wiki/xacro">


  <xacro:macro name="visual_and_collision_origin">
    <origin xyz="0 0 0" rpy="0 0 0"/>
  </xacro:macro>

  <xacro:macro name="visual_and_collision_geometry" params="link_name">
    <geometry>
      <mesh filename="package://flip1_description/meshes/${link_name}.STL"/>
    </geometry>
  </xacro:macro>

  <xacro:macro name="visual_and_collision_for_link" params="material_name  gen_link_name">
    <visual>
      <xacro:visual_and_collision_origin/>
      <xacro:visual_and_collision_geometry link_name="${gen_link_name}"/>
      <material name="${material_name}"/>
    </visual>
    <collision>
      <xacro:visual_and_collision_origin/>
      <xacro:visual_and_collision_geometry link_name="${gen_link_name}"/>
    </collision>
  </xacro:macro>

  <xacro:macro name="link_tag" params="link material mass *inertial_origin **interia_matrix">
    <link name="${link}">
      <xacro:visual_and_collision_for_link material_name="${material}" gen_link_name="${link}"/>
      <inertial>
        <mass value="${mass}"/>
        <xacro:insert_block name="inertial_origin"/>
        <xacro:insert_block name="interia_matrix"/>
      </inertial>
    </link>
  </xacro:macro>

  <xacro:link_tag link="base_link_arm" material="yellow" mass="1.7952">
    <origin xyz="1.2496E-07 -9.7714E-07 0.043629" rpy="0 0 0"/>
    <inertial_matrix>
      <inertia
        ixx="0.0042607" ixy="-2.5643E-08" ixz="-1.5443E-08"
        iyy="0.0042606" iyz="-1.6265E-08" izz="0.0059208"/>
    </inertial_matrix>
  </xacro:link_tag>

  <xacro:link_tag link="rotation_link" material="purple" mass="0.38734">
    <origin xyz="0 6.9389E-18 0.020598" rpy="0 0 0"/>
    <inertial_matrix>
      <inertia
        ixx="0.00049033" ixy="3.134E-20" ixz="4.3688E-20"
        iyy="0.00049033" iyz="-8.0027E-22" izz="0.00089765" />
    </inertial_matrix>
  </xacro:link_tag>

  <xacro:link_tag link="vertical_link" material="yellow" mass="2.8683">
    <origin xyz="0 0 0.14648" rpy="0 0 0"/>
    <inertial_matrix>
      <inertia
        ixx="0.024919" ixy="2.0329E-19" ixz="1.5006E-18"
        iyy="0.024772" iyz="2.04E-19" izz="0.0050439" />
    </inertial_matrix>
  </xacro:link_tag>

  <xacro:link_tag link="middle_arm_link" material="purple" mass="2.839">
    <origin xyz="5.5511E-17 -1.3878E-17 0.225" rpy="0 0 0"/>
    <inertial_matrix>
      <inertia
        ixx="0.072652" ixy="-5.421E-20" ixz="-7.9676E-19"
        iyy="0.073967" iyz="9.8764E-19" izz="0.002988" />
    </inertial_matrix>
  </xacro:link_tag>

  <xacro:link_tag link="end_link" material="yellow" mass="3.4568">
    <origin xyz="1.1102E-16 6.9389E-18 0.20744" rpy="0 0 0"/>
    <inertial_matrix>
      <inertia
        ixx="0.060655" ixy="7.1828E-19" ixz="4.0707E-18"
        iyy="0.059517" iyz="-2.6631E-18" izz="0.0051642" />
    </inertial_matrix>
  </xacro:link_tag>

  <xacro:link_tag link="gripper_holder_link" material="purple" mass="0.37775">
    <origin xyz="0 0 0.031338" rpy="0 0 0"/>
    <inertial_matrix>
      <inertia
        ixx="0.00058936" ixy="8.8938E-21" ixz="1.7754E-19" iyy="0.00056849"
        iyz="2.9434E-20" izz="0.00023348" />
    </inertial_matrix>
  </xacro:link_tag>

  <joint name="base_rotation_joint" type="revolute">
    <origin xyz="0 0 0.08" rpy="0 0 0.007562" />
    <parent link="base_link_arm" />
    <child link="rotation_link" />
    <axis xyz="0 0 -1" />
    <limit
      lower="-1.62"
      upper="0"
      effort="25"
      velocity="1" />
  </joint>

  <joint name="rotation_vertical_joint" type="fixed">
    <origin xyz="0 0 0.03" rpy="0 0 0" />
    <parent link="rotation_link" />
    <child link="vertical_link" />
  </joint>

  <joint name="vertical_middle_arm_joint" type="revolute">
    <origin xyz="0 0 0.3" rpy="0 0.31039 0" />
    <parent link="vertical_link" />
    <child link="middle_arm_link" />
    <axis xyz="0 -1 0" />
    <limit
      lower="-0.85"
      upper="0.33"
      effort="25"
      velocity="1" />
  </joint>

  <joint name="middle_end_joint" type="revolute">
    <origin xyz="0 0 0.45" rpy="0 1.1326 0" />
    <parent link="middle_arm_link" />
    <child link="end_link" />
    <axis xyz="0 1 0" />
    <limit
      lower="-2.0"
      upper="0.4"
      effort="25"
      velocity="1" />
  </joint>

  <joint name="gripper_holder_joint" type="revolute">
    <origin xyz="0 0 0.45" rpy="0 -0.43859 0" />
    <parent link="end_link" />
    <child link="gripper_holder_link" />
    <axis xyz="0 -1 0" />
    <limit
      lower="-3.0"
      upper="0.3"
      effort="25"
      velocity="1" />
  </joint>

</robot>
