<?xml version="1.0" ?>
<!-- =================================================================================== -->
<!-- |    This document was autogenerated by xacro from robot.xacro                    | -->
<!-- |    EDITING THIS FILE BY HAND IS NOT RECOMMENDED                                 | -->
<!-- =================================================================================== -->
<robot name="bot_manipulator" xmlns:xacro="https://www.ros.org/wiki/xacro">
  <material name="blue">
    <color rgba="0 0 1 1"/>
  </material>
  <material name="red">
    <color rgba="1 0 0 1"/>
  </material>
  <material name="green">
    <color rgba="0 1 0 1"/>
  </material>
  <material name="purple">
    <color rgba="1 0 1 1"/>
  </material>
  <material name="orange">
    <color rgba="1.0 0.423529411765 0.0392156862745 1"/>
  </material>
  <material name="yellow">
    <color rgba="1.0 1.0 0 1"/>
  </material>
  <material name="brown">
    <color rgba="0.619607843137 0.407843137255 0.164705882353 1"/>
  </material>
  --&gt;


  <link name="base_link_bot">
    <visual>
      <origin rpy="0 0 0" xyz="0 0 0"/>
      <geometry>
        <mesh filename="package://flip1_description/meshes/base_link_bot.STL"/>
      </geometry>
      <material name="blue"/>
    </visual>
    <collision>
      <origin rpy="0 0 0" xyz="0 0 0"/>
      <geometry>
        <mesh filename="package://flip1_description/meshes/base_link_bot.STL"/>
      </geometry>
    </collision>
    <inertial>
      <mass value="9.976679411"/>
      <origin rpy="0 0 0" xyz="-1.84685805937335E-06 0 0.015"/>
      <inertia ixx="0.187958008238022" ixy="3.08331692261721E-07" ixz="3.17637355220364E-19" iyy="0.381816176166743" iyz="1.41513138596527E-18" izz="0.568277677102426"/>
    </inertial>
  </link>
  <link name="link1">
    <visual>
      <origin rpy="0 0 0" xyz="0 0 0"/>
      <geometry>
        <mesh filename="package://flip1_description/meshes/link1.STL"/>
      </geometry>
      <material name="orange"/>
    </visual>
    <collision>
      <origin rpy="0 0 0" xyz="0 0 0"/>
      <geometry>
        <mesh filename="package://flip1_description/meshes/link1.STL"/>
      </geometry>
    </collision>
    <inertial>
      <mass value="1.0019"/>
      <origin rpy="0 0 0" xyz="-1.1102E-16 -0.36 0.0026615"/>
      <inertia ixx="0.03933" ixy="5.6898E-21" ixz="8.3057E-21" iyy="0.00026796" iyz="-2.4157E-19" izz="0.039273"/>
    </inertial>
  </link>
  <link name="link2">
    <visual>
      <origin rpy="0 0 0" xyz="0 0 0"/>
      <geometry>
        <mesh filename="package://flip1_description/meshes/link2.STL"/>
      </geometry>
      <material name="orange"/>
    </visual>
    <collision>
      <origin rpy="0 0 0" xyz="0 0 0"/>
      <geometry>
        <mesh filename="package://flip1_description/meshes/link2.STL"/>
      </geometry>
    </collision>
    <inertial>
      <mass value="1.0019"/>
      <origin rpy="0 0 0" xyz="-1.11022302462516E-16 -0.36 0.00266148520433351"/>
      <inertia ixx="0.0393298433372476" ixy="1.31346575687572E-21" ixz="8.30571622249648E-21" iyy="0.000267958739020857" iyz="-9.65217337723654E-20" izz="0.0392729406311258"/>
    </inertial>
  </link>
  <link name="link3">
    <visual>
      <origin rpy="0 0 0" xyz="0 0 0"/>
      <geometry>
        <mesh filename="package://flip1_description/meshes/link3.STL"/>
      </geometry>
      <material name="purple"/>
    </visual>
    <collision>
      <origin rpy="0 0 0" xyz="0 0 0"/>
      <geometry>
        <mesh filename="package://flip1_description/meshes/link3.STL"/>
      </geometry>
    </collision>
    <inertial>
      <mass value="0.95841"/>
      <origin rpy="0 0 0" xyz="0 -2.7756E-17 0"/>
      <inertia ixx="0.00172" ixy="6.5405E-20" ixz="7.1492E-20" iyy="0.0019649" iyz="-1.0822E-19" izz="0.00172"/>
    </inertial>
  </link>
  <link name="link4">
    <visual>
      <origin rpy="0 0 0" xyz="0 0 0"/>
      <geometry>
        <mesh filename="package://flip1_description/meshes/link4.STL"/>
      </geometry>
      <material name="purple"/>
    </visual>
    <collision>
      <origin rpy="0 0 0" xyz="0 0 0"/>
      <geometry>
        <mesh filename="package://flip1_description/meshes/link4.STL"/>
      </geometry>
    </collision>
    <inertial>
      <mass value="0.95841"/>
      <origin rpy="0 0 0" xyz="0 -1.1102E-16 0"/>
      <inertia ixx="0.00172" ixy="3.8103E-20" ixz="7.1492E-20" iyy="0.0019649" iyz="-8.0921E-20" izz="0.00172"/>
    </inertial>
  </link>
  <link name="link5">
    <visual>
      <origin rpy="0 0 0" xyz="0 0 0"/>
      <geometry>
        <mesh filename="package://flip1_description/meshes/link5.STL"/>
      </geometry>
      <material name="purple"/>
    </visual>
    <collision>
      <origin rpy="0 0 0" xyz="0 0 0"/>
      <geometry>
        <mesh filename="package://flip1_description/meshes/link5.STL"/>
      </geometry>
    </collision>
    <inertial>
      <mass value="0.95841"/>
      <origin rpy="0 0 0" xyz="1.11022302462516E-16 -2.77555756156289E-17 0"/>
      <inertia ixx="0.00172004064353737" ixy="9.19911852675595E-22" ixz="5.42101086242752E-20" iyy="0.00196493476186237" iyz="-9.05839369835372E-20" izz="0.00172004064353737"/>
    </inertial>
  </link>
  <link name="link6">
    <visual>
      <origin rpy="0 0 0" xyz="0 0 0"/>
      <geometry>
        <mesh filename="package://flip1_description/meshes/link6.STL"/>
      </geometry>
      <material name="purple"/>
    </visual>
    <collision>
      <origin rpy="0 0 0" xyz="0 0 0"/>
      <geometry>
        <mesh filename="package://flip1_description/meshes/link6.STL"/>
      </geometry>
    </collision>
    <inertial>
      <mass value="0.95841"/>
      <origin rpy="0 0 0" xyz="1.1102E-16 -1.1102E-16 0"/>
      <inertia ixx="0.00172" ixy="-1.7049E-20" ixz="2.1684E-19" iyy="0.0019649" iyz="-9.2729E-20" izz="0.00172"/>
    </inertial>
  </link>
  <joint name="joint1" type="fixed">
    <origin rpy="0 0 0" xyz="0.16597 0.36 -0.04"/>
    <parent link="base_link_bot"/>
    <child link="link1"/>
  </joint>
  <joint name="joint2" type="fixed">
    <origin rpy="0 0 0" xyz="-0.16597 0.36 -0.04"/>
    <parent link="base_link_bot"/>
    <child link="link2"/>
  </joint>
  <joint name="joint3" type="continuous">
    <origin rpy="0 0 0" xyz="0 -0.041744 0"/>
    <parent link="link1"/>
    <child link="link3"/>
    <axis xyz="0 1 0"/>
  </joint>
  <joint name="joint4" type="continuous">
    <origin rpy="0 0 0" xyz="0 -0.67826 0"/>
    <parent link="link1"/>
    <child link="link4"/>
    <axis xyz="0 1 0"/>
  </joint>
  <joint name="joint5" type="continuous">
    <origin rpy="0 0.082724 0" xyz="0 -0.041744 0"/>
    <parent link="link2"/>
    <child link="link5"/>
    <axis xyz="0 1 0"/>
  </joint>
  <joint name="joint6" type="continuous">
    <origin rpy="0 -0.55404 0" xyz="0 -0.67826 0"/>
    <parent link="link2"/>
    <child link="link6"/>
    <axis xyz="0 1 0"/>
  </joint>
  <link name="base_link_arm">
    <visual>
      <origin rpy="0 0 0" xyz="0 0 0"/>
      <geometry>
        <mesh filename="package://flip1_description/meshes/base_link_arm.STL"/>
      </geometry>
      <material name="yellow"/>
    </visual>
    <collision>
      <origin rpy="0 0 0" xyz="0 0 0"/>
      <geometry>
        <mesh filename="package://flip1_description/meshes/base_link_arm.STL"/>
      </geometry>
    </collision>
    <inertial>
      <mass value="1.7952"/>
      <origin rpy="0 0 0" xyz="1.2496E-07 -9.7714E-07 0.043629"/>
      <inertia ixx="0.0042607" ixy="-2.5643E-08" ixz="-1.5443E-08" iyy="0.0042606" iyz="-1.6265E-08" izz="0.0059208"/>
    </inertial>
  </link>
  <link name="rotation_link">
    <visual>
      <origin rpy="0 0 0" xyz="0 0 0"/>
      <geometry>
        <mesh filename="package://flip1_description/meshes/rotation_link.STL"/>
      </geometry>
      <material name="purple"/>
    </visual>
    <collision>
      <origin rpy="0 0 0" xyz="0 0 0"/>
      <geometry>
        <mesh filename="package://flip1_description/meshes/rotation_link.STL"/>
      </geometry>
    </collision>
    <inertial>
      <mass value="0.38734"/>
      <origin rpy="0 0 0" xyz="0 6.9389E-18 0.020598"/>
      <inertia ixx="0.00049033" ixy="3.134E-20" ixz="4.3688E-20" iyy="0.00049033" iyz="-8.0027E-22" izz="0.00089765"/>
    </inertial>
  </link>
  <link name="vertical_link">
    <visual>
      <origin rpy="0 0 0" xyz="0 0 0"/>
      <geometry>
        <mesh filename="package://flip1_description/meshes/vertical_link.STL"/>
      </geometry>
      <material name="yellow"/>
    </visual>
    <collision>
      <origin rpy="0 0 0" xyz="0 0 0"/>
      <geometry>
        <mesh filename="package://flip1_description/meshes/vertical_link.STL"/>
      </geometry>
    </collision>
    <inertial>
      <mass value="2.8683"/>
      <origin rpy="0 0 0" xyz="0 0 0.14648"/>
      <inertia ixx="0.024919" ixy="2.0329E-19" ixz="1.5006E-18" iyy="0.024772" iyz="2.04E-19" izz="0.0050439"/>
    </inertial>
  </link>
  <link name="middle_arm_link">
    <visual>
      <origin rpy="0 0 0" xyz="0 0 0"/>
      <geometry>
        <mesh filename="package://flip1_description/meshes/middle_arm_link.STL"/>
      </geometry>
      <material name="purple"/>
    </visual>
    <collision>
      <origin rpy="0 0 0" xyz="0 0 0"/>
      <geometry>
        <mesh filename="package://flip1_description/meshes/middle_arm_link.STL"/>
      </geometry>
    </collision>
    <inertial>
      <mass value="2.839"/>
      <origin rpy="0 0 0" xyz="5.5511E-17 -1.3878E-17 0.225"/>
      <inertia ixx="0.072652" ixy="-5.421E-20" ixz="-7.9676E-19" iyy="0.073967" iyz="9.8764E-19" izz="0.002988"/>
    </inertial>
  </link>
  <link name="end_link">
    <visual>
      <origin rpy="0 0 0" xyz="0 0 0"/>
      <geometry>
        <mesh filename="package://flip1_description/meshes/end_link.STL"/>
      </geometry>
      <material name="yellow"/>
    </visual>
    <collision>
      <origin rpy="0 0 0" xyz="0 0 0"/>
      <geometry>
        <mesh filename="package://flip1_description/meshes/end_link.STL"/>
      </geometry>
    </collision>
    <inertial>
      <mass value="3.4568"/>
      <origin rpy="0 0 0" xyz="1.1102E-16 6.9389E-18 0.20744"/>
      <inertia ixx="0.060655" ixy="7.1828E-19" ixz="4.0707E-18" iyy="0.059517" iyz="-2.6631E-18" izz="0.0051642"/>
    </inertial>
  </link>
  <link name="gripper_holder_link">
    <visual>
      <origin rpy="0 0 0" xyz="0 0 0"/>
      <geometry>
        <mesh filename="package://flip1_description/meshes/gripper_holder_link.STL"/>
      </geometry>
      <material name="purple"/>
    </visual>
    <collision>
      <origin rpy="0 0 0" xyz="0 0 0"/>
      <geometry>
        <mesh filename="package://flip1_description/meshes/gripper_holder_link.STL"/>
      </geometry>
    </collision>
    <inertial>
      <mass value="0.37775"/>
      <origin rpy="0 0 0" xyz="0 0 0.031338"/>
      <inertia ixx="0.00058936" ixy="8.8938E-21" ixz="1.7754E-19" iyy="0.00056849" iyz="2.9434E-20" izz="0.00023348"/>
    </inertial>
  </link>
  <joint name="base_rotation_joint" type="continuous">
    <origin rpy="0 0 0.007562" xyz="0 0 0.08"/>
    <parent link="base_link_arm"/>
    <child link="rotation_link"/>
    <axis xyz="0 0 -1"/>
  </joint>
  <joint name="rotation_vertical_joint" type="fixed">
    <origin rpy="0 0 0" xyz="0 0 0.03"/>
    <parent link="rotation_link"/>
    <child link="vertical_link"/>
  </joint>
  <joint name="vertical_middle_arm_joint" type="revolute">
    <origin rpy="0 0.31039 0" xyz="0 0 0.3"/>
    <parent link="vertical_link"/>
    <child link="middle_arm_link"/>
    <axis xyz="0 -1 0"/>
    <limit effort="25" lower="-3.14" upper="3.14" velocity="1"/>
  </joint>
  <joint name="middle_end_joint" type="revolute">
    <origin rpy="0 1.1326 0" xyz="0 0 0.45"/>
    <parent link="middle_arm_link"/>
    <child link="end_link"/>
    <axis xyz="0 1 0"/>
    <limit effort="25" lower="-3.14" upper="3.14" velocity="1"/>
  </joint>
  <joint name="gripper_holder_joint" type="revolute">
    <origin rpy="0 -0.43859 0" xyz="0 0 0.45"/>
    <parent link="end_link"/>
    <child link="gripper_holder_link"/>
    <axis xyz="0 -1 0"/>
    <limit effort="25" lower="-3.14" upper="3.14" velocity="1"/>
  </joint>
  <!-- This URDF was automatically created by SolidWorks to URDF Exporter! Originally created by Stephen Brawner (brawner@gmail.com)
     Commit Version: 1.4.4-24-g24328f6  Build Version: 1.5.7084.36479
     For more information, please see http://wiki.ros.org/sw_urdf_exporter -->
  <link name="base_link_gripper">
    <visual>
      <origin rpy="0 0 0" xyz="0 0 0"/>
      <geometry>
        <mesh filename="package://flip1_description/meshes/base_link_gripper.STL"/>
      </geometry>
      <material name="orange"/>
    </visual>
    <collision>
      <origin rpy="0 0 0" xyz="0 0 0"/>
      <geometry>
        <mesh filename="package://flip1_description/meshes/base_link_gripper.STL"/>
      </geometry>
    </collision>
    <inertial>
      <mass value="0.98099"/>
      <origin rpy="0 0 0" xyz="0 0.14142 0.00016012"/>
      <inertia ixx="0.003388" ixy="-1.1855E-19" ixz="-1.5339E-20" iyy="0.0012787" iyz="-4.4891E-06" izz="0.0044032"/>
    </inertial>
  </link>
  <link name="gear1_link">
    <visual>
      <origin rpy="0 0 0" xyz="0 0 0"/>
      <geometry>
        <mesh filename="package://flip1_description/meshes/gear1_link.STL"/>
      </geometry>
      <material name="red"/>
    </visual>
    <collision>
      <origin rpy="0 0 0" xyz="0 0 0"/>
      <geometry>
        <mesh filename="package://flip1_description/meshes/gear1_link.STL"/>
      </geometry>
    </collision>
    <inertial>
      <mass value="0.02723"/>
      <origin rpy="0 0 0" xyz="-2.77555756156289E-17 0.0175862034544711 5.55111512312578E-17"/>
      <inertia ixx="3.02981038903534E-05" ixy="1.6940658945086E-21" ixz="7.49263431833363E-22" iyy="4.50525088859917E-06" iyz="1.5400867235027E-21" izz="3.43494877805828E-05"/>
    </inertial>
  </link>
  <link name="finger_gear1_link">
    <visual>
      <origin rpy="0 0 0" xyz="0 0 0"/>
      <geometry>
        <mesh filename="package://flip1_description/meshes/finger_gear1_link.STL"/>
      </geometry>
      <material name="blue"/>
    </visual>
    <collision>
      <origin rpy="0 0 0" xyz="0 0 0"/>
      <geometry>
        <mesh filename="package://flip1_description/meshes/finger_gear1_link.STL"/>
      </geometry>
    </collision>
    <inertial>
      <mass value="0.17145"/>
      <origin rpy="0 0 0" xyz="-0.012289 0.101 0"/>
      <inertia ixx="0.0007122" ixy="4.0775E-05" ixz="4.039E-21" iyy="3.2189E-05" iyz="-6.5264E-21" izz="0.00069867"/>
    </inertial>
  </link>
  <link name="gear2_link">
    <visual>
      <origin rpy="0 0 0" xyz="0 0 0"/>
      <geometry>
        <mesh filename="package://flip1_description/meshes/gear2_link.STL"/>
      </geometry>
      <material name="red"/>
    </visual>
    <collision>
      <origin rpy="0 0 0" xyz="0 0 0"/>
      <geometry>
        <mesh filename="package://flip1_description/meshes/gear2_link.STL"/>
      </geometry>
    </collision>
    <inertial>
      <mass value="0.02723"/>
      <origin rpy="0 0 0" xyz="4.33006840808159E-06 0.0177884712258021 5.55111512312578E-17"/>
      <inertia ixx="3.0626740029709E-05" ixy="-1.15573930909179E-09" ixz="-1.4165993432485E-21" iyy="4.4831636497222E-06" iyz="4.26143905320326E-22" izz="3.46553024908243E-05"/>
    </inertial>
  </link>
  <link name="finger_gear2_link">
    <visual>
      <origin rpy="0 0 0" xyz="0 0 0"/>
      <geometry>
        <mesh filename="package://flip1_description/meshes/finger_gear2_link.STL"/>
      </geometry>
      <material name="blue"/>
    </visual>
    <collision>
      <origin rpy="0 0 0" xyz="0 0 0"/>
      <geometry>
        <mesh filename="package://flip1_description/meshes/finger_gear2_link.STL"/>
      </geometry>
    </collision>
    <inertial>
      <mass value="0.17145"/>
      <origin rpy="0 0 0" xyz="-0.012289 0.101 -5.5511E-17"/>
      <inertia ixx="0.0007122" ixy="4.0775E-05" ixz="-3.8232E-21" iyy="3.2189E-05" iyz="5.6109E-21" izz="0.00069867"/>
    </inertial>
  </link>
  <joint name="base_gear1_joint" type="revolute">
    <origin rpy="0 0 0.78573" xyz="-0.0275 0.17 0.025"/>
    <parent link="base_link_gripper"/>
    <child link="gear1_link"/>
    <axis xyz="0 0 1"/>
    <limit effort="25" lower="-3.14" upper="3.14" velocity="1"/>
  </joint>
  <joint name="finger_gear1_joint" type="revolute">
    <origin rpy="-3.1416 0 2.3612" xyz="0 0.099495 -0.025"/>
    <parent link="gear1_link"/>
    <child link="finger_gear1_link"/>
    <axis xyz="0 0 -1"/>
    <limit effort="25" lower="-3.14" upper="3.14" velocity="1"/>
  </joint>
  <joint name="base_gear2_joint" type="revolute">
    <origin rpy="0 0 -0.78573" xyz="0.0275 0.17 0.025"/>
    <parent link="base_link_gripper"/>
    <child link="gear2_link"/>
    <axis xyz="0 0 -1"/>
    <limit effort="25" lower="-3.14" upper="3.14" velocity="1"/>
  </joint>
  <joint name="finger_gear2_joint" type="revolute">
    <origin rpy="0 0 0.78989" xyz="0 0.1 -0.025"/>
    <parent link="gear2_link"/>
    <child link="finger_gear2_link"/>
    <axis xyz="0 0 -1"/>
    <limit effort="25" lower="-3.14" upper="3.14" velocity="1"/>
  </joint>
  <gazebo reference="base_link_bot">
    <material>Gazebo/Blue</material>
  </gazebo>
  <gazebo reference="link1">
    <material>Gazebo/Orange</material>
  </gazebo>
  <gazebo reference="link3">
    <material>Gazebo/Blue</material>
  </gazebo>
  <gazebo reference="link4">
    <material>Gazebo/Blue</material>
  </gazebo>
  <gazebo reference="link2">
    <material>Gazebo/Orange</material>
  </gazebo>
  <gazebo reference="link5">
    <material>Gazebo/Blue</material>
  </gazebo>
  <gazebo reference="link6">
    <material>Gazebo/Blue</material>
  </gazebo>
  <gazebo reference="base_link_arm">
    <material>Gazebo/Yellow</material>
  </gazebo>
  <gazebo reference="rotation_link">
    <material>Gazebo/Green</material>
  </gazebo>
  <gazebo reference="vertical_link">
    <material>Gazebo/Yellow</material>
  </gazebo>
  <gazebo reference="middle_arm_link">
    <material>Gazebo/Green</material>
  </gazebo>
  <gazebo reference="end_link">
    <material>Gazebo/Yellow</material>
  </gazebo>
  <gazebo reference="gripper_holder_link">
    <material>Gazebo/Green</material>
  </gazebo>
  <gazebo reference="base_link_gripper">
    <material>Gazebo/Red</material>
  </gazebo>
  <gazebo reference="gear1_link">
    <material>Gazebo/Grey</material>
  </gazebo>
  <gazebo reference="gear2_link">
    <material>Gazebo/Grey</material>
  </gazebo>
  <gazebo reference="finger_gear1_link">
    <material>Gazebo/SkyBlue</material>
  </gazebo>
  <gazebo reference="finger_gear2_link">
    <material>Gazebo/SkyBlue</material>
  </gazebo>
  <!--<xacro:include filename="$(find trial_bot)/urdf/kinect_sensor.urdf.xacro"/>-->
  <link name="base_link"/>
  <joint name="bot_world_joint" type="fixed">
    <origin rpy="0 0 0" xyz="0 0 0.1"/>
    <parent link="base_link"/>
    <child link="base_link_bot"/>
  </joint>
  <joint name="bot_manipulator_joint" type="fixed">
    <origin rpy=" 0 0 0" xyz="0 0 0.03 "/>
    <parent link="base_link_bot"/>
    <child link="base_link_arm"/>
  </joint>
  <joint name="manipulator_gripper_joint" type="revolute">
    <origin rpy="1.57075 0 0" xyz="0 0 0.063"/>
    <parent link="gripper_holder_link"/>
    <child link="base_link_gripper"/>
    <axis xyz="0 1 0"/>
    <limit effort="25" lower="-3.14" upper="3.14" velocity="1"/>
  </joint>
  <!--<joint name="base_link_kinect_joint" type="fixed">
    <origin xyz="0 0 1.3" rpy="0 0 0"/>
    <parent link="base_link"/>
    <child link="kinect_sensor_link"/>
  </joint>-->
</robot>

