<?xml version="1.0" ?>
<!-- =================================================================================== -->
<!-- |    This document was autogenerated by xacro from chassis_bot_xacro.xacro        | -->
<!-- |    EDITING THIS FILE BY HAND IS NOT RECOMMENDED                                 | -->
<!-- =================================================================================== -->
<robot name="bot" xmlns:xacro="https://www.ros.org/wiki/xacro">
  <link name="base_link_bot">
    <visual>
      <origin rpy="0 0 0" xyz="0 0 0"/>
      <geometry>
        <mesh filename="package://flip1_description/meshes/base_link_bot.STL"/>
      </geometry>
      <material name="blue"/>
    </visual>
    <collision>
      <origin rpy="0 0 0" xyz="0 0 0"/>
      <geometry>
        <mesh filename="package://flip1_description/meshes/base_link_bot.STL"/>
      </geometry>
    </collision>
    <inertial>
      <mass value="9.976679411"/>
      <origin rpy="0 0 0" xyz="-1.84685805937335E-06 0 0.015"/>
      <inertia ixx="0.187958008238022" ixy="3.08331692261721E-07" ixz="3.17637355220364E-19" iyy="0.381816176166743" iyz="1.41513138596527E-18" izz="0.568277677102426"/>
    </inertial>
  </link>
  <link name="link1">
    <visual>
      <origin rpy="0 0 0" xyz="0 0 0"/>
      <geometry>
        <mesh filename="package://flip1_description/meshes/link1.STL"/>
      </geometry>
      <material name="orange"/>
    </visual>
    <collision>
      <origin rpy="0 0 0" xyz="0 0 0"/>
      <geometry>
        <mesh filename="package://flip1_description/meshes/link1.STL"/>
      </geometry>
    </collision>
    <inertial>
      <mass value="1.0019"/>
      <origin rpy="0 0 0" xyz="-1.1102E-16 -0.36 0.0026615"/>
      <inertia ixx="0.03933" ixy="5.6898E-21" ixz="8.3057E-21" iyy="0.00026796" iyz="-2.4157E-19" izz="0.039273"/>
    </inertial>
  </link>
  <link name="link2">
    <visual>
      <origin rpy="0 0 0" xyz="0 0 0"/>
      <geometry>
        <mesh filename="package://flip1_description/meshes/link2.STL"/>
      </geometry>
      <material name="orange"/>
    </visual>
    <collision>
      <origin rpy="0 0 0" xyz="0 0 0"/>
      <geometry>
        <mesh filename="package://flip1_description/meshes/link2.STL"/>
      </geometry>
    </collision>
    <inertial>
      <mass value="1.0019"/>
      <origin rpy="0 0 0" xyz="-1.11022302462516E-16 -0.36 0.00266148520433351"/>
      <inertia ixx="0.0393298433372476" ixy="1.31346575687572E-21" ixz="8.30571622249648E-21" iyy="0.000267958739020857" iyz="-9.65217337723654E-20" izz="0.0392729406311258"/>
    </inertial>
  </link>
  <link name="link3">
    <visual>
      <origin rpy="0 0 0" xyz="0 0 0"/>
      <geometry>
        <mesh filename="package://flip1_description/meshes/link3.STL"/>
      </geometry>
      <material name="purple"/>
    </visual>
    <collision>
      <origin rpy="0 0 0" xyz="0 0 0"/>
      <geometry>
        <mesh filename="package://flip1_description/meshes/link3.STL"/>
      </geometry>
    </collision>
    <inertial>
      <mass value="0.95841"/>
      <origin rpy="0 0 0" xyz="0 -2.7756E-17 0"/>
      <inertia ixx="0.00172" ixy="6.5405E-20" ixz="7.1492E-20" iyy="0.0019649" iyz="-1.0822E-19" izz="0.00172"/>
    </inertial>
  </link>
  <link name="link4">
    <visual>
      <origin rpy="0 0 0" xyz="0 0 0"/>
      <geometry>
        <mesh filename="package://flip1_description/meshes/link4.STL"/>
      </geometry>
      <material name="purple"/>
    </visual>
    <collision>
      <origin rpy="0 0 0" xyz="0 0 0"/>
      <geometry>
        <mesh filename="package://flip1_description/meshes/link4.STL"/>
      </geometry>
    </collision>
    <inertial>
      <mass value="0.95841"/>
      <origin rpy="0 0 0" xyz="0 -1.1102E-16 0"/>
      <inertia ixx="0.00172" ixy="3.8103E-20" ixz="7.1492E-20" iyy="0.0019649" iyz="-8.0921E-20" izz="0.00172"/>
    </inertial>
  </link>
  <link name="link5">
    <visual>
      <origin rpy="0 0 0" xyz="0 0 0"/>
      <geometry>
        <mesh filename="package://flip1_description/meshes/link5.STL"/>
      </geometry>
      <material name="purple"/>
    </visual>
    <collision>
      <origin rpy="0 0 0" xyz="0 0 0"/>
      <geometry>
        <mesh filename="package://flip1_description/meshes/link5.STL"/>
      </geometry>
    </collision>
    <inertial>
      <mass value="0.95841"/>
      <origin rpy="0 0 0" xyz="1.11022302462516E-16 -2.77555756156289E-17 0"/>
      <inertia ixx="0.00172004064353737" ixy="9.19911852675595E-22" ixz="5.42101086242752E-20" iyy="0.00196493476186237" iyz="-9.05839369835372E-20" izz="0.00172004064353737"/>
    </inertial>
  </link>
  <link name="link6">
    <visual>
      <origin rpy="0 0 0" xyz="0 0 0"/>
      <geometry>
        <mesh filename="package://flip1_description/meshes/link6.STL"/>
      </geometry>
      <material name="purple"/>
    </visual>
    <collision>
      <origin rpy="0 0 0" xyz="0 0 0"/>
      <geometry>
        <mesh filename="package://flip1_description/meshes/link6.STL"/>
      </geometry>
    </collision>
    <inertial>
      <mass value="0.95841"/>
      <origin rpy="0 0 0" xyz="1.1102E-16 -1.1102E-16 0"/>
      <inertia ixx="0.00172" ixy="-1.7049E-20" ixz="2.1684E-19" iyy="0.0019649" iyz="-9.2729E-20" izz="0.00172"/>
    </inertial>
  </link>
  <joint name="joint1" type="fixed">
    <origin rpy="0 0 0" xyz="0.16597 0.36 -0.04"/>
    <parent link="base_link_bot"/>
    <child link="link1"/>
  </joint>
  <joint name="joint2" type="fixed">
    <origin rpy="0 0 0" xyz="-0.16597 0.36 -0.04"/>
    <parent link="base_link_bot"/>
    <child link="link2"/>
  </joint>
  <joint name="joint3" type="continuous">
    <origin rpy="0 0 0" xyz="0 -0.041744 0"/>
    <parent link="link1"/>
    <child link="link3"/>
    <axis xyz="0 1 0"/>
  </joint>
  <joint name="joint4" type="continuous">
    <origin rpy="0 0 0" xyz="0 -0.67826 0"/>
    <parent link="link1"/>
    <child link="link4"/>
    <axis xyz="0 1 0"/>
  </joint>
  <joint name="joint5" type="continuous">
    <origin rpy="0 0.082724 0" xyz="0 -0.041744 0"/>
    <parent link="link2"/>
    <child link="link5"/>
    <axis xyz="0 1 0"/>
  </joint>
  <joint name="joint6" type="continuous">
    <origin rpy="0 -0.55404 0" xyz="0 -0.67826 0"/>
    <parent link="link2"/>
    <child link="link6"/>
    <axis xyz="0 1 0"/>
  </joint>
</robot>

